Workbook
Name CATAGORY: LISTS!$A$2:$A$4
Name Ht_Hv: LISTS!$A$20:$A$21
Name K_cb: LISTS!#REF!
Name K_door: LISTS!$A$28:$A$31
Name K_dw: LISTS!$A$8:$A$9
Name K_dwf: LISTS!$A$38:$A$39
Name K_Lg: LISTS!$A$34:$A$35
Name K_ng: LISTS!$A$42:$A$43
Name K_rht: LISTS!$A$24:$A$25
Name K_tr: LISTS!$A$50:$A$51
Name K_uht: LISTS!$A$16:$A$17
Name K_vg: LISTS!$A$46:$A$47
Name K_vs: LISTS!$A$12:$A$13
Name LG: LISTS!$A$54:$A$55

Sheet Designer Inputs
A1: Component Weight Estimation Designer Inputs
A2: Direct Inputs Required for Yellow Cells (White Cells are auto-calculated)
A3: Use only English units as stated for values entered
A4: Source: Raymer Ch 15
A5: Aircraft Parameters | C5: Value | D5: Unit
A6: Estimated Crew Weight | B6: W_crew | C6: 300 | D6: lbs
A7: Estimated Passenger Weight | B7: W_passenger | C7: 300 | D7: lbs
A8: Estimated Other Payload Weight | B8: W_payload | C8: 120 | D8: lbs
A9: Esttimated Fuel Weight (Wf) | B9: Wf | C9: 222.02 | D9: lbs
A10: Estimated Empty Weight (We) | B10: We | C10: 1679.6 | D10: lbs
A11: Estimated Total Aircraft Weight (Wo) | B11: Wo | C11: =SUM(C6:C10) -> 2621.62 | D11: lbs
A12: Flight Design Gross Weight (@50% internal fuel) | B12: W_dg | C12: =$C$11-0.5*$C$9 -> 2510.61 | D12: lbs
A13: Ultimate Load Factor (1.5 factor of safety x Nmax) | B13: Nz | C13: =1.5*2.5 -> 3.75
A15: Main Wing Parameters | C15: Value | D15: Unit
A16: Wing Planform Area (Sref) | B16: S_w | C16: 174 | D16: ft^2
A17: Wing Aspect Ratio | B17: AR_w | C17: 7.32
A18: Wing Thickness to Chord Ratio at Root | B18: t/c_root | C18: 0.12
A19: Wing Taper Ratio | B19: Taper_w | C19: 0.8
A20: Wing Sweep at c/4 (Quarter Chord) | B20: Sweep_w | C20: 0 | D20: deg
A21: Wing Span | B21: Bw | C21: 36.1 | D21: ft
A22: Wing Control Surface Area (ailerons, flaps, etc. Just the area of control surface, not the affected area used in calculating CLmax) | B22: S_csw | C22: 8 | D22: ft^2
A23: Delta Wing adjustment (0.768 if delta, otherwise 1) | B23: K_dw | C23: 1
A24: Variable Sweep wing adjustment (1.19 if variable, otherwise 1) | B24: K_vs | C24: 1
A25: Weight of Fuel in Wings (if no fuel in wings, must input a "1") | B25: W_fw | C25: 1
A26: Dynamic Pressure at Cruise | B26: q | C26: 22.5 | D26: lb/ft^2
A28: Horizontal Tail Parameters | C28: Value | D28: Unit
A29: All moving horizontal adjustment (1.143 if all moving, otherwise 1) | B29: K_uht | C29: 1
A30: Fuselage width at horizontal tail intersection | B30: Fw | C30: 2 | D30: ft
A31: Horizontal Tail Span | B31: Bh | C31: 11.22 | D31: ft
A32: Horizontal Tail Planform Area | B32: S_ht | C32: 21.56 | D32: ft^2
A33: Wing A.C. to Horizontail Tail A.C. length | B33: L_ht | C33: 14.96 | D33: ft
A34: Aircraft Pitch Radius Gyration (=0.3* L_ht) | B34: Ky | C34: =0.3*$C$33 -> 4.488
A35: Horz Tail Sweep at c/4 | B35: Sweep_ht | C35: 0 | D35: deg
A36: Horz Tail Aspect Ratio | B36: AR_ht | C36: 3.5
A37: Elevator Control Surface Area (if not all moving) | B37: Se | C37: 6 | D37: ft^2
A38: Horz Tail thickness to chord ratio @ root | B38: t/c_root_ht | C38: 0.1
A39: Horz Tail Taper Ratio | B39: Taper_ht | C39: 0.8
A41: Vertical Tail Parameters | C41: Value | D41: Unit
A42: T-Tail Adjustment (0 for conventional tail, 1.0 for t-tail) | B42: Ht/Hv | C42: 0
A43: Wing A.C. to Vertical Tail A.C. length | B43: L_vt | C43: 14.86 | D43: ft
...

Sheet Group Weight Statement
A1: Aircraft Weights & Balance
A2: Direct Inputs Required for Yellow Cells (White Cells are auto-calculated)
A3: Category of Aircraft (Select Category of Aircraft from Pull-Down Menu)
A4: General Aviation/Prop Transport
A6: Group Weight Statement
A7: (Items in Red Italicizes not inluded in Empty Weight Estimate and only used in CG Analysis)
A8: Estimated Total Aircraft Weight (Wo) | B8: ='Designer Inputs'!$C$11 -> 2621.62 | C8: lb
A9: Esttimated Fuel Weight (Wf) | B9: ='Designer Inputs'!$C$9 -> 222.02 | C9: lb
A10: Estimated Empty Weight (We) | B10: ='Designer Inputs'!$C$10 -> 1679.6 | C10: lb
A11: Flight Design Gross Weight (@50% internal fuel) | B11: ='Designer Inputs'!$C$12 -> 2510.61 | C11: lb
A12: Ultimate Load Factor (1.5 factor of safety x Nmax) | B12: ='Designer Inputs'!$C$13 -> 3.75
B14: Component Weight (lbs) | C14: Component CG X-location (ft) x = 0 @ nose, centroid of component
A16: Structure Group
A17: Wing | B17: {=_xlfn.IFS($A$4="Fighter",0.0103*'Designer Inputs'!$C$23*'Designer Inputs'!$C$24*('Designer Inputs'!$C$12*'Designer Inputs'!$C$13)^0.5*'Designer Inputs'!$C$16^0.622*'Designer Inputs'!$C$17^0.785*'Designer Inputs'!$C$18^-0.4*(1+'Designer Inputs'!$C$19)^0.05*(COS('Designer Inputs'!$C$20*PI()/180))^-1*'Designer Inputs'!$C$22^0.04,$A$4="Bomber/Large Jet Transport",0.0051*('Designer Inputs'!$C$12*'Designer Inputs'!$C$13)^0.557*'Designer Inputs'!$C$16^0.649*'Designer Inputs'!$C$17^0.5*'Designer Inputs'!$C$18^-0.4*(1+'Designer Inputs'!$C$19)^0.1*(COS('Designer Inputs'!$C$20*PI()/180))^-1*'Designer Inputs'!$C$22^0.1,$A$4="General Aviation/Prop Transport",0.036*'Designer Inputs'!$C$16^0.758*'Designer Inputs'!$C$25^0.0035*('Designer Inputs'!$C$17/((COS('Designer Inputs'!C20*PI()/180))^2))^0.6*'Designer Inputs'!$C$26^0.006*'Designer Inputs'!$C$18^0.04*((100*'Designer Inputs'!$C$18)/(COS('Designer Inputs'!$C$20*PI()/180)))^-0.3*('Designer Inputs'!$C$13*'Designer Inputs'!$C$12)^0.49)} -> 233.36655 | C17: 27.277834
A18: Horizontal Tail | B18: {=_xlfn.IFS($A$4="Fighter",3.316*(1+'Designer Inputs'!$C$30/'Designer Inputs'!$C$31)^-2*('Designer Inputs'!$C$12*'Designer Inputs'!$C$13/1000)^0.26*'Designer Inputs'!$C$32^0.806,$A$4="Bomber/Large Jet Transport",0.0379*'Designer Inputs'!$C$29*(1+'Designer Inputs'!$C$30/'Designer Inputs'!$C$31)^-0.25*'Designer Inputs'!$C$12^0.639*'Designer Inputs'!$C$13^0.1*'Designer Inputs'!$C$32^0.75*'Designer Inputs'!$C$33^-1*'Designer Inputs'!$C$34^0.704*(COS('Designer Inputs'!$C$35*PI()/180))^-1*'Designer Inputs'!$C$36^0.166*(1+'Designer Inputs'!$C$37/'Designer Inputs'!$C$32)^0.1,$A$4="General Aviation/Prop Transport",0.016*('Designer Inputs'!$C$13*'Designer Inputs'!$C$12)^0.414*'Designer Inputs'!$C$26^0.168*'Designer Inputs'!$C$32^0.896*(100*'Designer Inputs'!$C$38/COS('Designer Inputs'!$C$35*PI()/180))^-0.12*('Designer Inputs'!$C$36/((COS('Designer Inputs'!$C$35*PI()/180))^2))^0.043*'Designer Inputs'!$C$39^-0.02)} -> 15.02196 | C18: 41.392221
A19: Vertical Tail | B19: {=_xlfn.IFS($A$4="Fighter",0.452*'Designer Inputs'!$C$48*(1+'Designer Inputs'!$C$42)^0.5*('Designer Inputs'!$C$12*'Designer Inputs'!$C$13)^0.488*'Designer Inputs'!$C$44^0.718*'Designer Inputs'!C49^0.341*'Designer Inputs'!$C$43^-1*(1+'Designer Inputs'!$C$50/'Designer Inputs'!$C$44)^0.348*'Designer Inputs'!$C$46^0.223*(1+'Designer Inputs'!$C$51)^0.25*(COS('Designer Inputs'!$C$45*PI()/180))^-0.323,$A$4="Bomber/Large Jet Transport",0.0026*(1+'Designer Inputs'!$C$42)^0.225*'Designer Inputs'!$C$12^0.556*'Designer Inputs'!$C$13^0.536*'Designer Inputs'!$C$43^-0.5*'Designer Inputs'!$C$44^0.5*'Designer Inputs'!$C$52^0.875*(COS('Designer Inputs'!$C$45*PI()/180))^-1*'Designer Inputs'!$C$46^0.35*'Designer Inputs'!$C$47^-0.5,$A$4="General Aviation/Prop Transport",0.073*(1+0.2*'Designer Inputs'!$C$42)*('Designer Inputs'!$C$13*'Designer Inputs'!$C$12)^0.376*'Designer Inputs'!$C$26^0.122*'Designer Inputs'!$C$44^0.873*(100*'Designer Inputs'!$C$47/COS('Designer Inputs'!$C$45*PI()/180))^-0.49*('Designer Inputs'!$C$46/((COS('Designer Inputs'!$C$45*PI()/180))^2))^0.357*'Designer Inputs'!$C$51^0.039)} -> 10.089131 | C19: 40.848838
A20: Fuselage | B20: {=_xlfn.IFS($A$4="Fighter",0.499*'Designer Inputs'!$C$64*'Designer Inputs'!$C$12^0.35*'Designer Inputs'!$C$13^0.25*'Designer Inputs'!$C$57^0.5*'Designer Inputs'!$C$60^0.849*'Designer Inputs'!$C$61^0.685,$A$4="Bomber/Large Jet Transport",0.328*'Designer Inputs'!$C$55*'Designer Inputs'!$C$56*('Designer Inputs'!$C$12*'Designer Inputs'!$C$13)^0.5*'Designer Inputs'!$C$57^0.25*'Designer Inputs'!$C$59^0.302*(1+'Designer Inputs'!$C$63)^0.04*'Designer Inputs'!$C$62^0.1,$A$4="General Aviation/Prop Transport",0.052*'Designer Inputs'!$C$59^1.086*('Designer Inputs'!$C$13*'Designer Inputs'!$C$12)^0.177*'Designer Inputs'!$C$33^-0.051*'Designer Inputs'!$C$62^-0.072*'Designer Inputs'!$C$26^0.241+'Designer Inputs'!$C$66)} -> 488.58554 | C20: 23.25
A21: Propulsion Group
A22: Jet Engine 1 Totals | B22: =SUM($B$23:$B$24) -> 0 | C22: 35.960217
A23: Jet Engine 1 | B23: ='Designer Inputs'!$C$71 -> 0
A24: Jet Engine 1 Nacelles | B24: {=_xlfn.IFS($A$4="Fighter",0,$A$4="Bomber/Large Jet Transport",0.6724*'Designer Inputs'!$C$74*'Designer Inputs'!$C$75^0.1*'Designer Inputs'!$C$76^0.294*'Designer Inputs'!$C$13^0.119*'Designer Inputs'!$C$84^0.611*'Designer Inputs'!$C$77^0.224,$A$4="General Aviation/Prop Transport",0)} -> 0
A25: Jet Engine 2 Totals | B25: =IF('Designer Inputs'!$C$69>1,$B$22,0) -> 0
A26: Jet Engine 2 | B26: =IF('Designer Inputs'!$C$69>1,$B$23,0) -> 0
A27: Jet Engine 2 Nacelles | B27: =IF('Designer Inputs'!$C$69>1,$B$24,0) -> 0
A28: Jet Engine 3 Totals | B28: =IF('Designer Inputs'!$C$69>2,$B$22,0) -> 0
A29: Jet Engine 3 | B29: =IF('Designer Inputs'!$C$69>2,$B$23,0) -> 0
A30: Jet Engine 3 Nacelles | B30: =IF('Designer Inputs'!$C$69>2,$B$24,0) -> 0
A31: Jet Engine 4 Totals | B31: =IF('Designer Inputs'!$C$69>3,$B$22,0) -> 0
A32: Jet Engine 4 | B32: =IF('Designer Inputs'!$C$69>3,$B$23,0) -> 0
A33: Jet Engine 4 Nacelles | B33: =IF('Designer Inputs'!$C$69>3,$B$24,0) -> 0
A34: Jet Engine Mounts | B34: {=_xlfn.IFS($A$4="Fighter",0.013*'Designer Inputs'!$C$69^0.795*'Designer Inputs'!$C$70^0.579*'Designer Inputs'!$C$13,$A$4="Bomber/Large Jet Transport",0,$A$4="General Aviation/Prop Transport",0)} -> 0 | C34: 35.960217
A35: Jet Engine Air Inlet System | B35: {=_xlfn.IFS($A$4="Fighter",13.29*'Designer Inputs'!$C$78*'Designer Inputs'!$C$79^0.643*'Designer Inputs'!$C$81^0.182*'Designer Inputs'!$C$69^1.498*('Designer Inputs'!$C$80/'Designer Inputs'!$C$79)^-0.373*'Designer Inputs'!$C$82,$A$4="Bomber/Large Jet Transport",0,$A$4="General Aviation/Prop Transport",0)} -> 0 | C35: 23
A37: Engine+Prop+Mount 1 | B37: {=_xlfn.IFS($A$4="Fighter",0,$A$4="Bomber/Large Jet Transport",0,$A$4="General Aviation/Prop Transport",2.575*'Designer Inputs'!$C$87^0.922)} -> 517.86858
A38: Engine+Prop+Mount 2 | B38: =IF('Designer Inputs'!$C$88>1,'Group Weight Statement'!$B$37,0) -> 0
A39: Engine+Prop+Mount 3 | B39: =IF('Designer Inputs'!$C$88>2,'Group Weight Statement'!$B$37,0) -> 0
A40: Engine+Prop+Mount 4 | B40: =IF('Designer Inputs'!$C$88>3,'Group Weight Statement'!$B$37,0) -> 0
A41: Engine+Prop+Mount 5 | B41: =IF('Designer Inputs'!$C$88>4,'Group Weight Statement'!$B$37,0) -> 0
A42: Engine+Prop+Mount 6 | B42: =IF('Designer Inputs'!$C$88>5,'Group Weight Statement'!$B$37,0) -> 0
A44: Fuel Tanks 1 | B44: =$B$9/3 -> 74.006667 | C44: 24
A45: Fuel Tanks 2 | B45: =$B$9/3 -> 74.006667 | C45: 27
...

Sheet LISTS
A1: Aircraft Category
A2: Fighter
A3: Bomber/Large Jet Transport
A4: General Aviation/Prop Transport
A6: Parameters
A7: K_dw
A8: 1
A9: 0.768
A11: K_vs
A12: 1
A13: 1.19
A15: K_uht
A16: 1
A17: 1.143
A19: Ht/Hv
A20: 0
A21: 1
A23: K_rht
A24: 1
A25: 1.047
A27: K_door
A28: 1
A29: 1.06
A30: 1.12
A31: 1.25
A33: K_Lg
A34: 1
A35: 1.12
A37: K_dwf
A38: 1
A39: 0.774
A41: K_ng
A42: 1
A43: 1.017
A45: K_vg
A46: 1
A47: 1.62
A49: K_tr
A50: 1
A51: 1.18
...
